<?xml version="1.0" encoding="UTF-8"?>
<testng-results skipped="0" failed="2" ignored="0" total="6" passed="4">
  <reporter-output>
  </reporter-output>
  <suite name="Test suite" duration-ms="185" started-at="2020-02-20T02:32:53 IST" finished-at="2020-02-20T02:32:53 IST">
    <groups>
    </groups>
    <test name="Sample Test" duration-ms="185" started-at="2020-02-20T02:32:53 IST" finished-at="2020-02-20T02:32:53 IST">
      <class name="listeners.TestNGLIstnersDemo">
        <test-method status="PASS" signature="Test1()[pri:0, instance:listeners.TestNGLIstnersDemo@32709393]" name="Test1" duration-ms="24" started-at="2020-02-20T02:32:53 IST" finished-at="2020-02-20T02:32:53 IST">
          <reporter-output>
          </reporter-output>
        </test-method> <!-- Test1 -->
        <test-method status="FAIL" signature="Test2()[pri:0, instance:listeners.TestNGLIstnersDemo@32709393]" name="Test2" duration-ms="10" started-at="2020-02-20T02:32:53 IST" finished-at="2020-02-20T02:32:53 IST">
          <exception class="java.lang.AssertionError">
            <message>
              <![CDATA[did not expect to find [true] but found [false]]]>
            </message>
            <full-stacktrace>
              <![CDATA[java.lang.AssertionError: did not expect to find [true] but found [false]
at org.testng.Assert.fail(Assert.java:97)
at org.testng.Assert.failNotEquals(Assert.java:969)
at org.testng.Assert.assertTrue(Assert.java:43)
at org.testng.Assert.assertTrue(Assert.java:53)
at listeners.TestNGLIstnersDemo.Test2(TestNGLIstnersDemo.java:20)
at sun.reflect.NativeMethodAccessorImpl.invoke0(Native Method)
at sun.reflect.NativeMethodAccessorImpl.invoke(Unknown Source)
at sun.reflect.DelegatingMethodAccessorImpl.invoke(Unknown Source)
at java.lang.reflect.Method.invoke(Unknown Source)
at org.testng.internal.MethodInvocationHelper.invokeMethod(MethodInvocationHelper.java:133)
at org.testng.internal.TestInvoker.invokeMethod(TestInvoker.java:584)
at org.testng.internal.TestInvoker.invokeTestMethod(TestInvoker.java:172)
at org.testng.internal.MethodRunner.runInSequence(MethodRunner.java:46)
at org.testng.internal.TestInvoker$MethodInvocationAgent.invoke(TestInvoker.java:804)
at org.testng.internal.TestInvoker.invokeTestMethods(TestInvoker.java:145)
at org.testng.internal.TestMethodWorker.invokeTestMethods(TestMethodWorker.java:146)
at org.testng.internal.TestMethodWorker.run(TestMethodWorker.java:128)
at java.util.ArrayList.forEach(Unknown Source)
at org.testng.TestRunner.privateRun(TestRunner.java:770)
at org.testng.TestRunner.run(TestRunner.java:591)
at org.testng.SuiteRunner.runTest(SuiteRunner.java:402)
at org.testng.SuiteRunner.runSequentially(SuiteRunner.java:396)
at org.testng.SuiteRunner.privateRun(SuiteRunner.java:355)
at org.testng.SuiteRunner.run(SuiteRunner.java:304)
at org.testng.SuiteRunnerWorker.runSuite(SuiteRunnerWorker.java:53)
at org.testng.SuiteRunnerWorker.run(SuiteRunnerWorker.java:96)
at org.testng.TestNG.runSuitesSequentially(TestNG.java:1180)
at org.testng.TestNG.runSuitesLocally(TestNG.java:1102)
at org.testng.TestNG.runSuites(TestNG.java:1032)
at org.testng.TestNG.run(TestNG.java:1000)
at org.testng.remote.AbstractRemoteTestNG.run(AbstractRemoteTestNG.java:115)
at org.testng.remote.RemoteTestNG.initAndRun(RemoteTestNG.java:251)
at org.testng.remote.RemoteTestNG.main(RemoteTestNG.java:77)
]]>
            </full-stacktrace>
          </exception> <!-- java.lang.AssertionError -->
          <reporter-output>
          </reporter-output>
        </test-method> <!-- Test2 -->
        <test-method status="PASS" signature="Test3()[pri:0, instance:listeners.TestNGLIstnersDemo@32709393]" name="Test3" duration-ms="3" started-at="2020-02-20T02:32:53 IST" finished-at="2020-02-20T02:32:53 IST">
          <reporter-output>
          </reporter-output>
        </test-method> <!-- Test3 -->
      </class> <!-- listeners.TestNGLIstnersDemo -->
      <class name="listeners.TestNGLIstnersDemo2">
        <test-method status="PASS" signature="Test4()[pri:0, instance:listeners.TestNGLIstnersDemo2@3d99d22e]" name="Test4" duration-ms="3" started-at="2020-02-20T02:32:53 IST" finished-at="2020-02-20T02:32:53 IST">
          <reporter-output>
          </reporter-output>
        </test-method> <!-- Test4 -->
        <test-method status="FAIL" signature="Test5()[pri:0, instance:listeners.TestNGLIstnersDemo2@3d99d22e]" name="Test5" duration-ms="2" started-at="2020-02-20T02:32:53 IST" finished-at="2020-02-20T02:32:53 IST">
          <exception class="java.lang.AssertionError">
            <message>
              <![CDATA[did not expect to find [true] but found [false]]]>
            </message>
            <full-stacktrace>
              <![CDATA[java.lang.AssertionError: did not expect to find [true] but found [false]
at org.testng.Assert.fail(Assert.java:97)
at org.testng.Assert.failNotEquals(Assert.java:969)
at org.testng.Assert.assertTrue(Assert.java:43)
at org.testng.Assert.assertTrue(Assert.java:53)
at listeners.TestNGLIstnersDemo2.Test5(TestNGLIstnersDemo2.java:20)
at sun.reflect.NativeMethodAccessorImpl.invoke0(Native Method)
at sun.reflect.NativeMethodAccessorImpl.invoke(Unknown Source)
at sun.reflect.DelegatingMethodAccessorImpl.invoke(Unknown Source)
at java.lang.reflect.Method.invoke(Unknown Source)
at org.testng.internal.MethodInvocationHelper.invokeMethod(MethodInvocationHelper.java:133)
at org.testng.internal.TestInvoker.invokeMethod(TestInvoker.java:584)
at org.testng.internal.TestInvoker.invokeTestMethod(TestInvoker.java:172)
at org.testng.internal.MethodRunner.runInSequence(MethodRunner.java:46)
at org.testng.internal.TestInvoker$MethodInvocationAgent.invoke(TestInvoker.java:804)
at org.testng.internal.TestInvoker.invokeTestMethods(TestInvoker.java:145)
at org.testng.internal.TestMethodWorker.invokeTestMethods(TestMethodWorker.java:146)
at org.testng.internal.TestMethodWorker.run(TestMethodWorker.java:128)
at java.util.ArrayList.forEach(Unknown Source)
at org.testng.TestRunner.privateRun(TestRunner.java:770)
at org.testng.TestRunner.run(TestRunner.java:591)
at org.testng.SuiteRunner.runTest(SuiteRunner.java:402)
at org.testng.SuiteRunner.runSequentially(SuiteRunner.java:396)
at org.testng.SuiteRunner.privateRun(SuiteRunner.java:355)
at org.testng.SuiteRunner.run(SuiteRunner.java:304)
at org.testng.SuiteRunnerWorker.runSuite(SuiteRunnerWorker.java:53)
at org.testng.SuiteRunnerWorker.run(SuiteRunnerWorker.java:96)
at org.testng.TestNG.runSuitesSequentially(TestNG.java:1180)
at org.testng.TestNG.runSuitesLocally(TestNG.java:1102)
at org.testng.TestNG.runSuites(TestNG.java:1032)
at org.testng.TestNG.run(TestNG.java:1000)
at org.testng.remote.AbstractRemoteTestNG.run(AbstractRemoteTestNG.java:115)
at org.testng.remote.RemoteTestNG.initAndRun(RemoteTestNG.java:251)
at org.testng.remote.RemoteTestNG.main(RemoteTestNG.java:77)
]]>
            </full-stacktrace>
          </exception> <!-- java.lang.AssertionError -->
          <reporter-output>
          </reporter-output>
        </test-method> <!-- Test5 -->
        <test-method status="PASS" signature="Test6()[pri:0, instance:listeners.TestNGLIstnersDemo2@3d99d22e]" name="Test6" duration-ms="7" started-at="2020-02-20T02:32:53 IST" finished-at="2020-02-20T02:32:53 IST">
          <reporter-output>
          </reporter-output>
        </test-method> <!-- Test6 -->
      </class> <!-- listeners.TestNGLIstnersDemo2 -->
    </test> <!-- Sample Test -->
  </suite> <!-- Test suite -->
</testng-results>
